<?xml version='1.0'?>
<robot name="simple_model" xmlns:xacro="http://ros.org/wiki/xacro">

  <link name="world"/>


  <link name='link_0'>
    <inertial>
      <origin xyz="0 0 0.5" rpy="0 0 0"/>
      <mass value="1"/>
      <inertia
        ixx="0.166667" ixy="0.0" ixz="0.0"
        iyy="0.166667" iyz="0.0"
        izz="0.166667"/>
    </inertial>

    <visual>
      <origin rpy="0 0 0" xyz = "0 0 0.5"/>
      <geometry>
        <box size="0.2 0.2 1"/>
      </geometry>
    </visual>

    <collision>
      <origin xyz="0 0 0.5" rpy="0 0 0"/>
      <geometry>
        <box size="0.2 0.2 1"/>
      </geometry>
    </collision>
  </link>  


  <link name='link_1'>
    <inertial>
      <origin xyz="0 0 0.1" rpy="0 0 0"/>
      <mass value="1"/>
      <inertia
        ixx="0.166667" ixy="0.0" ixz="0.0"
        iyy="0.166667" iyz="0.0"
        izz="0.166667"/>
    </inertial>

    <visual>
      <origin rpy="0 0 0" xyz = "0 0 0.1"/>
      <geometry>
        <box size="1 0.2 0.2"/>
      </geometry>
    </visual>

    <collision>
      <origin rpy="0 0 0" xyz = "0 0 0.1"/>      
      <geometry>
        <box size="1 0.2 0.2"/>
      </geometry>
    </collision>
  </link>  


  <joint name="joint_0" type="fixed">
    <parent link="world"/>
    <child link="link_0"/>
  </joint>

  <joint name="joint_1" type="continuous">
    <axis xyz="0 0 1"/>
    <origin rpy="0 0 0" xyz="0 0 1"/>
    <parent link = "link_0"/>
    <child link="link_1"/>
    <dynamics damping="0.7"/>
  </joint>


<transmission name="tran_1">
    <type>transmission_interface/SimpleTransmission</type>
    <joint name="joint_1">
      <hardwareInterface>hardware_interface/EffortJointInterface</hardwareInterface>
    </joint>
    <actuator name="motor_1">
      <hardwareInterface>hardware_interface/EffortJointInterface</hardwareInterface>
      <mechanicalReduction>1</mechanicalReduction>
    </actuator>
  </transmission>

  <gazebo>
    <plugin name="gazebo_ros_control" filename="libgazebo_ros_control.so">
      <robotNamespace>/simple_model</robotNamespace>
    </plugin>
  </gazebo> 

<link name='ray'>
    <inertial>
      <origin xyz="0 0 0" rpy="0 0 0"/>
      <mass value="0.001"/>
      <inertia
        ixx="0.0166667" ixy="0.0" ixz="0.0"
        iyy="0.0166667" iyz="0.0"
        izz="0.0166667"/>
    </inertial>

    <visual>
      <origin xyz = "0 0 0" rpy="0 0 0"/>
      <geometry>
        <cylinder length="0.1" radius = "0.04"/>
      </geometry>
    </visual>

    <collision>
      <geometry>
        <cylinder length="0.1" radius = "0.04"/>
      </geometry>
    </collision>

  </link>
  
<joint name="link_1_ray" type="fixed">
      <parent link = "link_1"/>
      <child link="ray"/>
      <origin rpy="1.5707 0 0" xyz = "0.5 0 0.05"/>
  </joint> 
  
<gazebo reference="ray">
    <sensor type="ray" name="lidar">
      <pose>0 0 0 0 0 0</pose>
      <visualize>true</visualize>
      <update_rate>30</update_rate>
      <ray>
        <scan>
          <horizontal>
            <samples>32</samples>
            <resolution>1</resolution>
            <min_angle>-0.53529248</min_angle>
            <max_angle>0.18622663</max_angle>
          </horizontal>
        </scan>
        <range>
          <min>0.05</min>
          <max>70</max>
          <resolution>0.02</resolution>
        </range>
      </ray>
      <plugin name = "gazebo_ros_lidar_publisher" filename = "libgazebo_ros_laser.so">
        <topicName>/simple_lidar/scan</topicName>
        <frameName>lidar_link</frameName>
      </plugin>
    </sensor>
  </gazebo>

</robot>
